Workbook
Name DANH_MUC: '4. CÀI ĐẶT'!$A$2:$A$32

Sheet 0. TEST NHANH
B1: ⚡ TEST NHANH — DÒNG TIỀN THÁNG VỪA RỒI (5 phút)
B2: Điền 6 ô vàng cho MỘT THÁNG ĐÃ KHÉP SỔ (thường là tháng vừa rồi). Kết quả hiện ngay bên dưới. Test xong, muốn theo dõi thật hằng ngày → sang sheet '1. NHẬP DỮ LIỆU'.
B3: Tháng đang test (ghi cho nhớ, vd: 6/2026): | C3: 6/2026
B4: BƯỚC 1 — ĐIỀN 6 Ô (số mẫu đang điền sẵn — xóa đi, điền số của bạn)
B5: ① Tiền có ĐẦU tháng test (= dư cuối tháng trước đó dồn sang — lỗ dồn thì điền số ÂM) | C5: 35000000 | D5: VD test tháng 6 → điền số dư cuối tháng 5
B6: ② Tổng tiền khách trả trong tháng test | C6: 190000000 | D6: App ngân hàng + sổ/két — cộng nhanh
B7: ③ Tổng chi cho spa trong tháng (nhà, lương, hàng, ads…) — KHÔNG tính tiền mình rút | C7: 151000000 | D7: Cộng nhẩm các khoản lớn là đủ
B8: ④ Tiền mình RÚT tiêu riêng trong tháng | C8: 20000000 | D8: Thành thật nha 😄
B9: ⑤ Tiền spa còn lại CUỐI tháng test (két + tài khoản) | C9: 29000000 | D9: Số tại ngày cuối tháng — KHÔNG lấy số hôm nay
B10: ⑥ Nợ buổi gói với khách hiện tại (gói đã bán, chưa làm xong) | C10: 115000000 | D10: Ước nhanh từ 5–10 khách gói gần nhất. Chưa nắm → ĐỂ TRỐNG. Không bán gói → điền 0
B12: BƯỚC 2 — 4 CON SỐ NÓI THẬT
B13: ① TIỀN TIÊU ĐƯỢC THẬT SỰ (= tiền cuối kỳ − nợ khách) | C13: =IF($C$9="","Chưa tính được",IF($C$10="","Chưa tính được",$C$9-$C$10)) | D13: =IF($C$9="","⚪",IF($C$10="","⚪",IF($C$9-$C$10<0,"🔴",IF(AND($C$7<>"",$C$9-$C$10<$C$7/2),"🟡","🟢"))))
B14: =IF($C$9="","Còn thiếu ô ⑤ (tiền spa còn lại cuối tháng test) — điền vào là số này hiện ngay.",IF($C$10="","Bạn chưa biết mình nợ khách bao nhiêu — đó chính là con số cần đi tìm đầu tiên (xem việc cần làm bên dưới).",IF($C$9-$C$10<0,"Nợ khách nhiều hơn tiền đang có: mỗi đồng tiêu thêm là tiêu vào tiền của khách.",IF($C$9-$C$10=0,"Vừa khít — không còn đệm an toàn nào.","Đây mới là số bạn thật sự được phép tiêu — không phải số trong két."))))
B15: ② TIỀN CỦA KHÁCH ĐANG GỬI TRONG KÉT (nợ dịch vụ) | C15: =IF($C$10="","Chưa đo được",$C$10) | D15: =IF(AND($C$9="",$C$10<>"",$C$10>0),"⚪",IF($C$10="","⚪",IF($C$10<=0,"🟢",IF($C$9<=0,"🔴",IF($C$10/$C$9<=0.5,"🟢",IF($C$10/$C$9<=1,"🟡","🔴"))))))
B16: =IF(AND($C$9="",$C$10<>"",$C$10>0),"Còn thiếu ô ⑤ (tiền còn cuối tháng) nên chưa biết tiền khách chiếm bao nhiêu phần trong két.",IF($C$10="","Chưa đo được — bảng vẫn chạy 2 chỉ số dưới.",IF($C$10<=0,"Không nợ gói — nhẹ gánh một mối lớn.",IF($C$9<=0,"Két gần trống trong khi vẫn còn nợ khách dịch vụ — mức báo động.",IF($C$10/$C$9<=0.5,"Trong tầm kiểm soát — nhớ để riêng phần này ra khi chi tiêu.",IF($C$10/$C$9<=1,"QUÁ NỬA tiền trong két là tiền của khách — cẩn trọng với mọi khoản chi lớn.","Nợ khách NHIỀU HƠN toàn bộ tiền đang có — két đầy hay vơi không còn nói lên điều gì."))))))
B17: ③ TIỀN KHÔNG LỜI GIẢI (đối chiếu sổ ↔ thực tế) | C17: =IF(OR($C$5="",$C$6="",$C$7="",$C$8="",$C$9=""),"Chưa đủ số",(($C$5+$C$6-$C$7-$C$8)-$C$9)) | D17: =IF(OR($C$5="",$C$6="",$C$7="",$C$8="",$C$9=""),"⚪",IF(ABS((($C$5+$C$6-$C$7-$C$8)-$C$9))<=0.1*$C$6,"🟢",IF(ABS((($C$5+$C$6-$C$7-$C$8)-$C$9))<=0.25*$C$6,"🟡","🔴")))
B18: =IF(OR($C$5="",$C$6="",$C$7="",$C$8="",$C$9=""),"Còn thiếu số ở BƯỚC 1 — phép đối chiếu này cần đủ 5 ô ① ② ③ ④ ⑤.",IF(ABS((($C$5+$C$6-$C$7-$C$8)-$C$9))<=0.1*$C$6,"Lệch trong biên sai số trí nhớ (dưới 10% tổng thu) — coi như khớp.",IF((($C$5+$C$6-$C$7-$C$8)-$C$9)>0,"Theo số bạn điền, đáng lẽ cuối tháng còn "&TEXT(($C$5+$C$6-$C$7-$C$8),"#,##0")&"đ — thực tế còn "&TEXT($C$9,"#,##0")&"đ. Khoản chênh này đã rời spa mà không có lời giải: chi không ghi, lẫn tiền túi, hoặc thất thoát.","Thực tế còn NHIỀU hơn sổ tính "&TEXT(ABS((($C$5+$C$6-$C$7-$C$8)-$C$9)),"#,##0")&"đ — thường do quên kể một khoản thu, hoặc tiền túi bù vào không ghi. Cũng là dấu hai túi đang lẫn nhau.")))
B19: ④ THÁNG RỒI, MÌNH SỐNG BẰNG TIỀN GÌ? (spa làm ra vs mình rút) | C19: =IF(OR($C$6="",$C$7="",$C$8=""),"Chưa đủ số","Làm ra "&TEXT(($C$6-$C$7),"#,##0")&" · Rút "&TEXT($C$8,"#,##0")) | D19: =IF(OR($C$6="",$C$7="",$C$8=""),"⚪",IF(($C$6-$C$7)<=0,IF($C$8>0,"🔴","🟡"),IF($C$8>($C$6-$C$7),"🟡",IF(AND($C$10<>"",$C$9-$C$10<0),"🟡","🟢"))))
B20: =IF(OR($C$6="",$C$7="",$C$8=""),"Còn thiếu số ở BƯỚC 1 — câu này cần 3 ô: ② tổng thu · ③ chi cho spa · ④ mình rút.",IF(($C$6-$C$7)<=0,IF($C$8>0,"Spa không làm ra đồng nào mà bạn vẫn rút "&TEXT($C$8,"#,##0")&"đ — toàn bộ khoản này lấy từ vốn cũ hoặc tiền ứng trước của khách.","Spa không làm ra — may là bạn cũng chưa rút. Câu hỏi là: bạn đang sống bằng gì?"),IF($C$8>($C$6-$C$7),"Spa làm ra "&TEXT(($C$6-$C$7),"#,##0")&"đ nhưng bạn rút "&TEXT($C$8,"#,##0")&"đ — phần chênh đang lấy từ két, không phải từ lợi nhuận.",IF(AND($C$10<>"",$C$9-$C$10<0),"Nhìn thì ổn — NHƯNG tiền tiêu được đang ÂM: trong số làm ra có tiền ứng trước của khách. Chưa được yên tâm.","Bạn đang sống bằng tiền spa làm ra — đúng nguồn. (Lưu ý: số làm ra chưa trừ phần buổi gói còn nợ — lãi thật thường thấp hơn.)"))))
B22: BƯỚC 3 — MỘT VIỆC LÀM NGAY (10–15 phút, bắt đầu từ hôm nay)
B23: =IF(AND($C$5="",$C$6="",$C$7="",$C$8="",$C$9="",$C$10=""),"Điền 6 ô ở BƯỚC 1 (số của một tháng đã khép sổ) — 5 phút thôi. Kết quả và việc cần làm sẽ hiện ngay tại đây.",IF(OR($C$5="",$C$6="",$C$7="",$C$8="",$C$9=""),"Còn ô trống ở BƯỚC 1. Điền nốt 5 ô ① ② ③ ④ ⑤ (riêng ô ⑥ chưa nắm thì cứ để trống) — bảng sẽ chỉ đúng một việc cần làm.",IF($C$10="","Mở note điện thoại, tạo trang ""SỔ GÓI"": ghi 10 khách mua gói gần nhất còn nhớ (tên · buổi còn lại · giá buổi). Từ nay bán gói mới nào ghi thêm 1 dòng ngay lúc thu tiền. Chưa đầy đủ không sao — từ hôm nay không phát sinh thêm khoản nợ vô hình nào nữa.",IF(AND($C$10>0,$C$9-$C$10<0),"Mở note điện thoại, tạo trang ""SỔ GÓI"": ghi 10 khách mua gói gần nhất còn nhớ (tên · buổi còn lại · giá buổi). Từ nay bán gói mới nào ghi thêm 1 dòng ngay lúc thu tiền. Chưa đầy đủ không sao — từ hôm nay không phát sinh thêm khoản nợ vô hình nào nữa.",IF(ABS((($C$5+$C$6-$C$7-$C$8)-$C$9))>0.1*$C$6,"Ngay bây giờ: mở app ngân hàng + đếm két → cộng thành MỘT con số ""tiền spa đang có hôm nay"", chụp màn hình kèm ngày. Hẹn 7 ngày sau làm lại. Hiệu 2 con số = lần đầu bạn NHÌN THẤY tuần này dư hay hụt.",IF(OR(($C$6-$C$7)<=0,$C$8>($C$6-$C$7)),"Chốt MỘT mức lương cho chính mình (tạm cũng được), đặt lịch chuyển đúng số đó một ngày cố định mỗi tháng. Lỡ cần lấy thêm từ két → ghi 1 dòng ""mượn của spa"". Ranh giới bắt đầu tồn tại từ hôm nay.","Sáu số này chưa lộ lỗ thủng gấp nào — việc của bạn là GIỮ NẾP: sang sheet '1. NHẬP DỮ LIỆU' dùng bảng theo dõi hằng ngày để tháng sau vẫn nói được những con số này trong 1 phút."))))))
B25: ➡️ Test xong: theo dõi thật hằng ngày ở sheet '1. NHẬP DỮ LIỆU' (dashboard tự chạy ở sheet '2. DASHBOARD'). Muốn biết VÌ SAO và sửa từ đâu → Chẩn Đoán Sức Khỏe Spa cùng Đàm Thanh Hoa (link ở cuối sheet '2. DASHBOARD').
B26: Giải Pháp Đàm Hoa · Đàm Thị Thanh Hoa — 15 năm nghề spa, 6 chi nhánh.

Sheet 1. NHẬP DỮ LIỆU
A1: 1️⃣ NHẬP DỮ LIỆU — chị chỉ điền ở tab này
A2: ① Spa của chị có bán gói / liệu trình trả trước không? → | D2: Có | E2: (trả lời 1 lần)
A3: ② Mỗi việc thu/chi = 1 dòng (nhập trong ngày hoặc 2–3 lần/tuần). Điền: NGÀY · HẠNG MỤC · SỐ TIỀN. Cột xám tự tính.
A4: NGÀY | B4: HẠNG MỤC (bấm ▼) | C4: SỐ TIỀN | D4: GHI CHÚ | E4: → VÀO KÉT | F4: sys_dt | G4: sys_cp | H4: sys_quy | I4: sys_nhom | J4: sys_thang | K4: sys_tc
A5: =MIN(DATE(YEAR(TODAY()),MONTH(TODAY()),1),TODAY()) | B5: ⚙️ Số dư đầu kỳ (tiền đang có sẵn) | C5: 30000000 | D5: Tiền có sẵn lúc bắt đầu | E5: =IF($B5="","",IF(LEFT($B5,1)="━","⚠️ Chọn hạng mục cụ thể",$C5*VLOOKUP($B5,'4. CÀI ĐẶT'!$A$2:$H$32,2,FALSE))) | F5: =IF($B5="",0,IF(LEFT($B5,1)="━",0,$C5*VLOOKUP($B5,'4. CÀI ĐẶT'!$A$2:$H$32,3,FALSE))) | G5: =IF($B5="",0,IF(LEFT($B5,1)="━",0,$C5*VLOOKUP($B5,'4. CÀI ĐẶT'!$A$2:$H$32,4,FALSE))) | H5: =IF($B5="",0,IF(LEFT($B5,1)="━",0,$C5*VLOOKUP($B5,'4. CÀI ĐẶT'!$A$2:$H$32,5,FALSE))) | I5: =IF($B5="","",IF(LEFT($B5,1)="━","",VLOOKUP($B5,'4. CÀI ĐẶT'!$A$2:$H$32,6,FALSE))) | J5: =IF($A5="","",EOMONTH($A5,0)) | K5: =IF($B5="",0,IF(LEFT($B5,1)="━",0,$C5*VLOOKUP($B5,'4. CÀI ĐẶT'!$A$2:$H$32,7,FALSE)))
A6: =MIN(DATE(YEAR(TODAY()),MONTH(TODAY()),2),TODAY()) | B6: 🎟️ Bán gói trả trước | C6: 90000000 | D6: 6 khách mua gói 12 buổi | E6: =IF($B6="","",IF(LEFT($B6,1)="━","⚠️ Chọn hạng mục cụ thể",$C6*VLOOKUP($B6,'4. CÀI ĐẶT'!$A$2:$H$32,2,FALSE))) | F6: =IF($B6="",0,IF(LEFT($B6,1)="━",0,$C6*VLOOKUP($B6,'4. CÀI ĐẶT'!$A$2:$H$32,3,FALSE))) | G6: =IF($B6="",0,IF(LEFT($B6,1)="━",0,$C6*VLOOKUP($B6,'4. CÀI ĐẶT'!$A$2:$H$32,4,FALSE))) | H6: =IF($B6="",0,IF(LEFT($B6,1)="━",0,$C6*VLOOKUP($B6,'4. CÀI ĐẶT'!$A$2:$H$32,5,FALSE))) | I6: =IF($B6="","",IF(LEFT($B6,1)="━","",VLOOKUP($B6,'4. CÀI ĐẶT'!$A$2:$H$32,6,FALSE))) | J6: =IF($A6="","",EOMONTH($A6,0)) | K6: =IF($B6="",0,IF(LEFT($B6,1)="━",0,$C6*VLOOKUP($B6,'4. CÀI ĐẶT'!$A$2:$H$32,7,FALSE)))
A7: =MIN(DATE(YEAR(TODAY()),MONTH(TODAY()),3),TODAY()) | B7: 💰 Khách lẻ trả tiền ngay | C7: 22000000 | D7: Khách lẻ tuần 1 | E7: =IF($B7="","",IF(LEFT($B7,1)="━","⚠️ Chọn hạng mục cụ thể",$C7*VLOOKUP($B7,'4. CÀI ĐẶT'!$A$2:$H$32,2,FALSE))) | F7: =IF($B7="",0,IF(LEFT($B7,1)="━",0,$C7*VLOOKUP($B7,'4. CÀI ĐẶT'!$A$2:$H$32,3,FALSE))) | G7: =IF($B7="",0,IF(LEFT($B7,1)="━",0,$C7*VLOOKUP($B7,'4. CÀI ĐẶT'!$A$2:$H$32,4,FALSE))) | H7: =IF($B7="",0,IF(LEFT($B7,1)="━",0,$C7*VLOOKUP($B7,'4. CÀI ĐẶT'!$A$2:$H$32,5,FALSE))) | I7: =IF($B7="","",IF(LEFT($B7,1)="━","",VLOOKUP($B7,'4. CÀI ĐẶT'!$A$2:$H$32,6,FALSE))) | J7: =IF($A7="","",EOMONTH($A7,0)) | K7: =IF($B7="",0,IF(LEFT($B7,1)="━",0,$C7*VLOOKUP($B7,'4. CÀI ĐẶT'!$A$2:$H$32,7,FALSE)))
A8: =MIN(DATE(YEAR(TODAY()),MONTH(TODAY()),5),TODAY()) | B8: 🏠 Thuê mặt bằng | C8: 25000000 | D8: Tiền nhà | E8: =IF($B8="","",IF(LEFT($B8,1)="━","⚠️ Chọn hạng mục cụ thể",$C8*VLOOKUP($B8,'4. CÀI ĐẶT'!$A$2:$H$32,2,FALSE))) | F8: =IF($B8="",0,IF(LEFT($B8,1)="━",0,$C8*VLOOKUP($B8,'4. CÀI ĐẶT'!$A$2:$H$32,3,FALSE))) | G8: =IF($B8="",0,IF(LEFT($B8,1)="━",0,$C8*VLOOKUP($B8,'4. CÀI ĐẶT'!$A$2:$H$32,4,FALSE))) | H8: =IF($B8="",0,IF(LEFT($B8,1)="━",0,$C8*VLOOKUP($B8,'4. CÀI ĐẶT'!$A$2:$H$32,5,FALSE))) | I8: =IF($B8="","",IF(LEFT($B8,1)="━","",VLOOKUP($B8,'4. CÀI ĐẶT'!$A$2:$H$32,6,FALSE))) | J8: =IF($A8="","",EOMONTH($A8,0)) | K8: =IF($B8="",0,IF(LEFT($B8,1)="━",0,$C8*VLOOKUP($B8,'4. CÀI ĐẶT'!$A$2:$H$32,7,FALSE)))
A9: =MIN(DATE(YEAR(TODAY()),MONTH(TODAY()),6),TODAY()) | B9: ✅ Giá trị dịch vụ gói đã làm trong tuần | C9: 18000000 | D9: Tuần 1: buổi gói đã làm | E9: =IF($B9="","",IF(LEFT($B9,1)="━","⚠️ Chọn hạng mục cụ thể",$C9*VLOOKUP($B9,'4. CÀI ĐẶT'!$A$2:$H$32,2,FALSE))) | F9: =IF($B9="",0,IF(LEFT($B9,1)="━",0,$C9*VLOOKUP($B9,'4. CÀI ĐẶT'!$A$2:$H$32,3,FALSE))) | G9: =IF($B9="",0,IF(LEFT($B9,1)="━",0,$C9*VLOOKUP($B9,'4. CÀI ĐẶT'!$A$2:$H$32,4,FALSE))) | H9: =IF($B9="",0,IF(LEFT($B9,1)="━",0,$C9*VLOOKUP($B9,'4. CÀI ĐẶT'!$A$2:$H$32,5,FALSE))) | I9: =IF($B9="","",IF(LEFT($B9,1)="━","",VLOOKUP($B9,'4. CÀI ĐẶT'!$A$2:$H$32,6,FALSE))) | J9: =IF($A9="","",EOMONTH($A9,0)) | K9: =IF($B9="",0,IF(LEFT($B9,1)="━",0,$C9*VLOOKUP($B9,'4. CÀI ĐẶT'!$A$2:$H$32,7,FALSE)))
A10: =MIN(DATE(YEAR(TODAY()),MONTH(TODAY()),8),TODAY()) | B10: 🧴 Mỹ phẩm · vật tư cho khách | C10: 12000000 | D10: Nhập mỹ phẩm | E10: =IF($B10="","",IF(LEFT($B10,1)="━","⚠️ Chọn hạng mục cụ thể",$C10*VLOOKUP($B10,'4. CÀI ĐẶT'!$A$2:$H$32,2,FALSE))) | F10: =IF($B10="",0,IF(LEFT($B10,1)="━",0,$C10*VLOOKUP($B10,'4. CÀI ĐẶT'!$A$2:$H$32,3,FALSE))) | G10: =IF($B10="",0,IF(LEFT($B10,1)="━",0,$C10*VLOOKUP($B10,'4. CÀI ĐẶT'!$A$2:$H$32,4,FALSE))) | H10: =IF($B10="",0,IF(LEFT($B10,1)="━",0,$C10*VLOOKUP($B10,'4. CÀI ĐẶT'!$A$2:$H$32,5,FALSE))) | I10: =IF($B10="","",IF(LEFT($B10,1)="━","",VLOOKUP($B10,'4. CÀI ĐẶT'!$A$2:$H$32,6,FALSE))) | J10: =IF($A10="","",EOMONTH($A10,0)) | K10: =IF($B10="",0,IF(LEFT($B10,1)="━",0,$C10*VLOOKUP($B10,'4. CÀI ĐẶT'!$A$2:$H$32,7,FALSE)))
A11: =MIN(DATE(YEAR(TODAY()),MONTH(TODAY()),10),TODAY()) | B11: 🎟️ Bán gói trả trước | C11: 60000000 | D11: Ưu đãi | E11: =IF($B11="","",IF(LEFT($B11,1)="━","⚠️ Chọn hạng mục cụ thể",$C11*VLOOKUP($B11,'4. CÀI ĐẶT'!$A$2:$H$32,2,FALSE))) | F11: =IF($B11="",0,IF(LEFT($B11,1)="━",0,$C11*VLOOKUP($B11,'4. CÀI ĐẶT'!$A$2:$H$32,3,FALSE))) | G11: =IF($B11="",0,IF(LEFT($B11,1)="━",0,$C11*VLOOKUP($B11,'4. CÀI ĐẶT'!$A$2:$H$32,4,FALSE))) | H11: =IF($B11="",0,IF(LEFT($B11,1)="━",0,$C11*VLOOKUP($B11,'4. CÀI ĐẶT'!$A$2:$H$32,5,FALSE))) | I11: =IF($B11="","",IF(LEFT($B11,1)="━","",VLOOKUP($B11,'4. CÀI ĐẶT'!$A$2:$H$32,6,FALSE))) | J11: =IF($A11="","",EOMONTH($A11,0)) | K11: =IF($B11="",0,IF(LEFT($B11,1)="━",0,$C11*VLOOKUP($B11,'4. CÀI ĐẶT'!$A$2:$H$32,7,FALSE)))
A12: =MIN(DATE(YEAR(TODAY()),MONTH(TODAY()),12),TODAY()) | B12: 💡 Điện · nước · internet | C12: 6000000 | E12: =IF($B12="","",IF(LEFT($B12,1)="━","⚠️ Chọn hạng mục cụ thể",$C12*VLOOKUP($B12,'4. CÀI ĐẶT'!$A$2:$H$32,2,FALSE))) | F12: =IF($B12="",0,IF(LEFT($B12,1)="━",0,$C12*VLOOKUP($B12,'4. CÀI ĐẶT'!$A$2:$H$32,3,FALSE))) | G12: =IF($B12="",0,IF(LEFT($B12,1)="━",0,$C12*VLOOKUP($B12,'4. CÀI ĐẶT'!$A$2:$H$32,4,FALSE))) | H12: =IF($B12="",0,IF(LEFT($B12,1)="━",0,$C12*VLOOKUP($B12,'4. CÀI ĐẶT'!$A$2:$H$32,5,FALSE))) | I12: =IF($B12="","",IF(LEFT($B12,1)="━","",VLOOKUP($B12,'4. CÀI ĐẶT'!$A$2:$H$32,6,FALSE))) | J12: =IF($A12="","",EOMONTH($A12,0)) | K12: =IF($B12="",0,IF(LEFT($B12,1)="━",0,$C12*VLOOKUP($B12,'4. CÀI ĐẶT'!$A$2:$H$32,7,FALSE)))
A13: =MIN(DATE(YEAR(TODAY()),MONTH(TODAY()),13),TODAY()) | B13: 📣 Quảng cáo · marketing | C13: 15000000 | D13: Ads Facebook | E13: =IF($B13="","",IF(LEFT($B13,1)="━","⚠️ Chọn hạng mục cụ thể",$C13*VLOOKUP($B13,'4. CÀI ĐẶT'!$A$2:$H$32,2,FALSE))) | F13: =IF($B13="",0,IF(LEFT($B13,1)="━",0,$C13*VLOOKUP($B13,'4. CÀI ĐẶT'!$A$2:$H$32,3,FALSE))) | G13: =IF($B13="",0,IF(LEFT($B13,1)="━",0,$C13*VLOOKUP($B13,'4. CÀI ĐẶT'!$A$2:$H$32,4,FALSE))) | H13: =IF($B13="",0,IF(LEFT($B13,1)="━",0,$C13*VLOOKUP($B13,'4. CÀI ĐẶT'!$A$2:$H$32,5,FALSE))) | I13: =IF($B13="","",IF(LEFT($B13,1)="━","",VLOOKUP($B13,'4. CÀI ĐẶT'!$A$2:$H$32,6,FALSE))) | J13: =IF($A13="","",EOMONTH($A13,0)) | K13: =IF($B13="",0,IF(LEFT($B13,1)="━",0,$C13*VLOOKUP($B13,'4. CÀI ĐẶT'!$A$2:$H$32,7,FALSE)))
A14: =MIN(DATE(YEAR(TODAY()),MONTH(TODAY()),14),TODAY()) | B14: ✅ Giá trị dịch vụ gói đã làm trong tuần | C14: 17000000 | D14: Tuần 2: buổi gói đã làm | E14: =IF($B14="","",IF(LEFT($B14,1)="━","⚠️ Chọn hạng mục cụ thể",$C14*VLOOKUP($B14,'4. CÀI ĐẶT'!$A$2:$H$32,2,FALSE))) | F14: =IF($B14="",0,IF(LEFT($B14,1)="━",0,$C14*VLOOKUP($B14,'4. CÀI ĐẶT'!$A$2:$H$32,3,FALSE))) | G14: =IF($B14="",0,IF(LEFT($B14,1)="━",0,$C14*VLOOKUP($B14,'4. CÀI ĐẶT'!$A$2:$H$32,4,FALSE))) | H14: =IF($B14="",0,IF(LEFT($B14,1)="━",0,$C14*VLOOKUP($B14,'4. CÀI ĐẶT'!$A$2:$H$32,5,FALSE))) | I14: =IF($B14="","",IF(LEFT($B14,1)="━","",VLOOKUP($B14,'4. CÀI ĐẶT'!$A$2:$H$32,6,FALSE))) | J14: =IF($A14="","",EOMONTH($A14,0)) | K14: =IF($B14="",0,IF(LEFT($B14,1)="━",0,$C14*VLOOKUP($B14,'4. CÀI ĐẶT'!$A$2:$H$32,7,FALSE)))
A15: =MIN(DATE(YEAR(TODAY()),MONTH(TODAY()),15),TODAY()) | B15: 👩 Lương cứng nhân viên | C15: 45000000 | D15: Lương 5 bạn | E15: =IF($B15="","",IF(LEFT($B15,1)="━","⚠️ Chọn hạng mục cụ thể",$C15*VLOOKUP($B15,'4. CÀI ĐẶT'!$A$2:$H$32,2,FALSE))) | F15: =IF($B15="",0,IF(LEFT($B15,1)="━",0,$C15*VLOOKUP($B15,'4. CÀI ĐẶT'!$A$2:$H$32,3,FALSE))) | G15: =IF($B15="",0,IF(LEFT($B15,1)="━",0,$C15*VLOOKUP($B15,'4. CÀI ĐẶT'!$A$2:$H$32,4,FALSE))) | H15: =IF($B15="",0,IF(LEFT($B15,1)="━",0,$C15*VLOOKUP($B15,'4. CÀI ĐẶT'!$A$2:$H$32,5,FALSE))) | I15: =IF($B15="","",IF(LEFT($B15,1)="━","",VLOOKUP($B15,'4. CÀI ĐẶT'!$A$2:$H$32,6,FALSE))) | J15: =IF($A15="","",EOMONTH($A15,0)) | K15: =IF($B15="",0,IF(LEFT($B15,1)="━",0,$C15*VLOOKUP($B15,'4. CÀI ĐẶT'!$A$2:$H$32,7,FALSE)))
A16: =MIN(DATE(YEAR(TODAY()),MONTH(TODAY()),16),TODAY()) | B16: 💰 Khách lẻ trả tiền ngay | C16: 18000000 | D16: Khách lẻ tuần 2 | E16: =IF($B16="","",IF(LEFT($B16,1)="━","⚠️ Chọn hạng mục cụ thể",$C16*VLOOKUP($B16,'4. CÀI ĐẶT'!$A$2:$H$32,2,FALSE))) | F16: =IF($B16="",0,IF(LEFT($B16,1)="━",0,$C16*VLOOKUP($B16,'4. CÀI ĐẶT'!$A$2:$H$32,3,FALSE))) | G16: =IF($B16="",0,IF(LEFT($B16,1)="━",0,$C16*VLOOKUP($B16,'4. CÀI ĐẶT'!$A$2:$H$32,4,FALSE))) | H16: =IF($B16="",0,IF(LEFT($B16,1)="━",0,$C16*VLOOKUP($B16,'4. CÀI ĐẶT'!$A$2:$H$32,5,FALSE))) | I16: =IF($B16="","",IF(LEFT($B16,1)="━","",VLOOKUP($B16,'4. CÀI ĐẶT'!$A$2:$H$32,6,FALSE))) | J16: =IF($A16="","",EOMONTH($A16,0)) | K16: =IF($B16="",0,IF(LEFT($B16,1)="━",0,$C16*VLOOKUP($B16,'4. CÀI ĐẶT'!$A$2:$H$32,7,FALSE)))
A17: =MIN(DATE(YEAR(TODAY()),MONTH(TODAY()),18),TODAY()) | B17: 💵 Hoa hồng · thưởng theo doanh số | C17: 8000000 | E17: =IF($B17="","",IF(LEFT($B17,1)="━","⚠️ Chọn hạng mục cụ thể",$C17*VLOOKUP($B17,'4. CÀI ĐẶT'!$A$2:$H$32,2,FALSE))) | F17: =IF($B17="",0,IF(LEFT($B17,1)="━",0,$C17*VLOOKUP($B17,'4. CÀI ĐẶT'!$A$2:$H$32,3,FALSE))) | G17: =IF($B17="",0,IF(LEFT($B17,1)="━",0,$C17*VLOOKUP($B17,'4. CÀI ĐẶT'!$A$2:$H$32,4,FALSE))) | H17: =IF($B17="",0,IF(LEFT($B17,1)="━",0,$C17*VLOOKUP($B17,'4. CÀI ĐẶT'!$A$2:$H$32,5,FALSE))) | I17: =IF($B17="","",IF(LEFT($B17,1)="━","",VLOOKUP($B17,'4. CÀI ĐẶT'!$A$2:$H$32,6,FALSE))) | J17: =IF($A17="","",EOMONTH($A17,0)) | K17: =IF($B17="",0,IF(LEFT($B17,1)="━",0,$C17*VLOOKUP($B17,'4. CÀI ĐẶT'!$A$2:$H$32,7,FALSE)))
A18: =MIN(DATE(YEAR(TODAY()),MONTH(TODAY()),20),TODAY()) | B18: 👑 Chủ rút tiền tiêu riêng | C18: 20000000 | D18: Chi tiêu gia đình | E18: =IF($B18="","",IF(LEFT($B18,1)="━","⚠️ Chọn hạng mục cụ thể",$C18*VLOOKUP($B18,'4. CÀI ĐẶT'!$A$2:$H$32,2,FALSE))) | F18: =IF($B18="",0,IF(LEFT($B18,1)="━",0,$C18*VLOOKUP($B18,'4. CÀI ĐẶT'!$A$2:$H$32,3,FALSE))) | G18: =IF($B18="",0,IF(LEFT($B18,1)="━",0,$C18*VLOOKUP($B18,'4. CÀI ĐẶT'!$A$2:$H$32,4,FALSE))) | H18: =IF($B18="",0,IF(LEFT($B18,1)="━",0,$C18*VLOOKUP($B18,'4. CÀI ĐẶT'!$A$2:$H$32,5,FALSE))) | I18: =IF($B18="","",IF(LEFT($B18,1)="━","",VLOOKUP($B18,'4. CÀI ĐẶT'!$A$2:$H$32,6,FALSE))) | J18: =IF($A18="","",EOMONTH($A18,0)) | K18: =IF($B18="",0,IF(LEFT($B18,1)="━",0,$C18*VLOOKUP($B18,'4. CÀI ĐẶT'!$A$2:$H$32,7,FALSE)))
A19: =MIN(DATE(YEAR(TODAY()),MONTH(TODAY()),20),TODAY()) | B19: 🪑 Mua máy móc · đầu tư lớn | C19: 60000000 | D19: Máy triệt lông | E19: =IF($B19="","",IF(LEFT($B19,1)="━","⚠️ Chọn hạng mục cụ thể",$C19*VLOOKUP($B19,'4. CÀI ĐẶT'!$A$2:$H$32,2,FALSE))) | F19: =IF($B19="",0,IF(LEFT($B19,1)="━",0,$C19*VLOOKUP($B19,'4. CÀI ĐẶT'!$A$2:$H$32,3,FALSE))) | G19: =IF($B19="",0,IF(LEFT($B19,1)="━",0,$C19*VLOOKUP($B19,'4. CÀI ĐẶT'!$A$2:$H$32,4,FALSE))) | H19: =IF($B19="",0,IF(LEFT($B19,1)="━",0,$C19*VLOOKUP($B19,'4. CÀI ĐẶT'!$A$2:$H$32,5,FALSE))) | I19: =IF($B19="","",IF(LEFT($B19,1)="━","",VLOOKUP($B19,'4. CÀI ĐẶT'!$A$2:$H$32,6,FALSE))) | J19: =IF($A19="","",EOMONTH($A19,0)) | K19: =IF($B19="",0,IF(LEFT($B19,1)="━",0,$C19*VLOOKUP($B19,'4. CÀI ĐẶT'!$A$2:$H$32,7,FALSE)))
E20: =IF($B20="","",IF(LEFT($B20,1)="━","⚠️ Chọn hạng mục cụ thể",$C20*VLOOKUP($B20,'4. CÀI ĐẶT'!$A$2:$H$32,2,FALSE))) | F20: =IF($B20="",0,IF(LEFT($B20,1)="━",0,$C20*VLOOKUP($B20,'4. CÀI ĐẶT'!$A$2:$H$32,3,FALSE))) | G20: =IF($B20="",0,IF(LEFT($B20,1)="━",0,$C20*VLOOKUP($B20,'4. CÀI ĐẶT'!$A$2:$H$32,4,FALSE))) | H20: =IF($B20="",0,IF(LEFT($B20,1)="━",0,$C20*VLOOKUP($B20,'4. CÀI ĐẶT'!$A$2:$H$32,5,FALSE))) | I20: =IF($B20="","",IF(LEFT($B20,1)="━","",VLOOKUP($B20,'4. CÀI ĐẶT'!$A$2:$H$32,6,FALSE))) | J20: =IF($A20="","",EOMONTH($A20,0)) | K20: =IF($B20="",0,IF(LEFT($B20,1)="━",0,$C20*VLOOKUP($B20,'4. CÀI ĐẶT'!$A$2:$H$32,7,FALSE)))
E21: =IF($B21="","",IF(LEFT($B21,1)="━","⚠️ Chọn hạng mục cụ thể",$C21*VLOOKUP($B21,'4. CÀI ĐẶT'!$A$2:$H$32,2,FALSE))) | F21: =IF($B21="",0,IF(LEFT($B21,1)="━",0,$C21*VLOOKUP($B21,'4. CÀI ĐẶT'!$A$2:$H$32,3,FALSE))) | G21: =IF($B21="",0,IF(LEFT($B21,1)="━",0,$C21*VLOOKUP($B21,'4. CÀI ĐẶT'!$A$2:$H$32,4,FALSE))) | H21: =IF($B21="",0,IF(LEFT($B21,1)="━",0,$C21*VLOOKUP($B21,'4. CÀI ĐẶT'!$A$2:$H$32,5,FALSE))) | I21: =IF($B21="","",IF(LEFT($B21,1)="━","",VLOOKUP($B21,'4. CÀI ĐẶT'!$A$2:$H$32,6,FALSE))) | J21: =IF($A21="","",EOMONTH($A21,0)) | K21: =IF($B21="",0,IF(LEFT($B21,1)="━",0,$C21*VLOOKUP($B21,'4. CÀI ĐẶT'!$A$2:$H$32,7,FALSE)))
E22: =IF($B22="","",IF(LEFT($B22,1)="━","⚠️ Chọn hạng mục cụ thể",$C22*VLOOKUP($B22,'4. CÀI ĐẶT'!$A$2:$H$32,2,FALSE))) | F22: =IF($B22="",0,IF(LEFT($B22,1)="━",0,$C22*VLOOKUP($B22,'4. CÀI ĐẶT'!$A$2:$H$32,3,FALSE))) | G22: =IF($B22="",0,IF(LEFT($B22,1)="━",0,$C22*VLOOKUP($B22,'4. CÀI ĐẶT'!$A$2:$H$32,4,FALSE))) | H22: =IF($B22="",0,IF(LEFT($B22,1)="━",0,$C22*VLOOKUP($B22,'4. CÀI ĐẶT'!$A$2:$H$32,5,FALSE))) | I22: =IF($B22="","",IF(LEFT($B22,1)="━","",VLOOKUP($B22,'4. CÀI ĐẶT'!$A$2:$H$32,6,FALSE))) | J22: =IF($A22="","",EOMONTH($A22,0)) | K22: =IF($B22="",0,IF(LEFT($B22,1)="━",0,$C22*VLOOKUP($B22,'4. CÀI ĐẶT'!$A$2:$H$32,7,FALSE)))
E23: =IF($B23="","",IF(LEFT($B23,1)="━","⚠️ Chọn hạng mục cụ thể",$C23*VLOOKUP($B23,'4. CÀI ĐẶT'!$A$2:$H$32,2,FALSE))) | F23: =IF($B23="",0,IF(LEFT($B23,1)="━",0,$C23*VLOOKUP($B23,'4. CÀI ĐẶT'!$A$2:$H$32,3,FALSE))) | G23: =IF($B23="",0,IF(LEFT($B23,1)="━",0,$C23*VLOOKUP($B23,'4. CÀI ĐẶT'!$A$2:$H$32,4,FALSE))) | H23: =IF($B23="",0,IF(LEFT($B23,1)="━",0,$C23*VLOOKUP($B23,'4. CÀI ĐẶT'!$A$2:$H$32,5,FALSE))) | I23: =IF($B23="","",IF(LEFT($B23,1)="━","",VLOOKUP($B23,'4. CÀI ĐẶT'!$A$2:$H$32,6,FALSE))) | J23: =IF($A23="","",EOMONTH($A23,0)) | K23: =IF($B23="",0,IF(LEFT($B23,1)="━",0,$C23*VLOOKUP($B23,'4. CÀI ĐẶT'!$A$2:$H$32,7,FALSE)))
E24: =IF($B24="","",IF(LEFT($B24,1)="━","⚠️ Chọn hạng mục cụ thể",$C24*VLOOKUP($B24,'4. CÀI ĐẶT'!$A$2:$H$32,2,FALSE))) | F24: =IF($B24="",0,IF(LEFT($B24,1)="━",0,$C24*VLOOKUP($B24,'4. CÀI ĐẶT'!$A$2:$H$32,3,FALSE))) | G24: =IF($B24="",0,IF(LEFT($B24,1)="━",0,$C24*VLOOKUP($B24,'4. CÀI ĐẶT'!$A$2:$H$32,4,FALSE))) | H24: =IF($B24="",0,IF(LEFT($B24,1)="━",0,$C24*VLOOKUP($B24,'4. CÀI ĐẶT'!$A$2:$H$32,5,FALSE))) | I24: =IF($B24="","",IF(LEFT($B24,1)="━","",VLOOKUP($B24,'4. CÀI ĐẶT'!$A$2:$H$32,6,FALSE))) | J24: =IF($A24="","",EOMONTH($A24,0)) | K24: =IF($B24="",0,IF(LEFT($B24,1)="━",0,$C24*VLOOKUP($B24,'4. CÀI ĐẶT'!$A$2:$H$32,7,FALSE)))
E25: =IF($B25="","",IF(LEFT($B25,1)="━","⚠️ Chọn hạng mục cụ thể",$C25*VLOOKUP($B25,'4. CÀI ĐẶT'!$A$2:$H$32,2,FALSE))) | F25: =IF($B25="",0,IF(LEFT($B25,1)="━",0,$C25*VLOOKUP($B25,'4. CÀI ĐẶT'!$A$2:$H$32,3,FALSE))) | G25: =IF($B25="",0,IF(LEFT($B25,1)="━",0,$C25*VLOOKUP($B25,'4. CÀI ĐẶT'!$A$2:$H$32,4,FALSE))) | H25: =IF($B25="",0,IF(LEFT($B25,1)="━",0,$C25*VLOOKUP($B25,'4. CÀI ĐẶT'!$A$2:$H$32,5,FALSE))) | I25: =IF($B25="","",IF(LEFT($B25,1)="━","",VLOOKUP($B25,'4. CÀI ĐẶT'!$A$2:$H$32,6,FALSE))) | J25: =IF($A25="","",EOMONTH($A25,0)) | K25: =IF($B25="",0,IF(LEFT($B25,1)="━",0,$C25*VLOOKUP($B25,'4. CÀI ĐẶT'!$A$2:$H$32,7,FALSE)))
E26: =IF($B26="","",IF(LEFT($B26,1)="━","⚠️ Chọn hạng mục cụ thể",$C26*VLOOKUP($B26,'4. CÀI ĐẶT'!$A$2:$H$32,2,FALSE))) | F26: =IF($B26="",0,IF(LEFT($B26,1)="━",0,$C26*VLOOKUP($B26,'4. CÀI ĐẶT'!$A$2:$H$32,3,FALSE))) | G26: =IF($B26="",0,IF(LEFT($B26,1)="━",0,$C26*VLOOKUP($B26,'4. CÀI ĐẶT'!$A$2:$H$32,4,FALSE))) | H26: =IF($B26="",0,IF(LEFT($B26,1)="━",0,$C26*VLOOKUP($B26,'4. CÀI ĐẶT'!$A$2:$H$32,5,FALSE))) | I26: =IF($B26="","",IF(LEFT($B26,1)="━","",VLOOKUP($B26,'4. CÀI ĐẶT'!$A$2:$H$32,6,FALSE))) | J26: =IF($A26="","",EOMONTH($A26,0)) | K26: =IF($B26="",0,IF(LEFT($B26,1)="━",0,$C26*VLOOKUP($B26,'4. CÀI ĐẶT'!$A$2:$H$32,7,FALSE)))
E27: =IF($B27="","",IF(LEFT($B27,1)="━","⚠️ Chọn hạng mục cụ thể",$C27*VLOOKUP($B27,'4. CÀI ĐẶT'!$A$2:$H$32,2,FALSE))) | F27: =IF($B27="",0,IF(LEFT($B27,1)="━",0,$C27*VLOOKUP($B27,'4. CÀI ĐẶT'!$A$2:$H$32,3,FALSE))) | G27: =IF($B27="",0,IF(LEFT($B27,1)="━",0,$C27*VLOOKUP($B27,'4. CÀI ĐẶT'!$A$2:$H$32,4,FALSE))) | H27: =IF($B27="",0,IF(LEFT($B27,1)="━",0,$C27*VLOOKUP($B27,'4. CÀI ĐẶT'!$A$2:$H$32,5,FALSE))) | I27: =IF($B27="","",IF(LEFT($B27,1)="━","",VLOOKUP($B27,'4. CÀI ĐẶT'!$A$2:$H$32,6,FALSE))) | J27: =IF($A27="","",EOMONTH($A27,0)) | K27: =IF($B27="",0,IF(LEFT($B27,1)="━",0,$C27*VLOOKUP($B27,'4. CÀI ĐẶT'!$A$2:$H$32,7,FALSE)))
E28: =IF($B28="","",IF(LEFT($B28,1)="━","⚠️ Chọn hạng mục cụ thể",$C28*VLOOKUP($B28,'4. CÀI ĐẶT'!$A$2:$H$32,2,FALSE))) | F28: =IF($B28="",0,IF(LEFT($B28,1)="━",0,$C28*VLOOKUP($B28,'4. CÀI ĐẶT'!$A$2:$H$32,3,FALSE))) | G28: =IF($B28="",0,IF(LEFT($B28,1)="━",0,$C28*VLOOKUP($B28,'4. CÀI ĐẶT'!$A$2:$H$32,4,FALSE))) | H28: =IF($B28="",0,IF(LEFT($B28,1)="━",0,$C28*VLOOKUP($B28,'4. CÀI ĐẶT'!$A$2:$H$32,5,FALSE))) | I28: =IF($B28="","",IF(LEFT($B28,1)="━","",VLOOKUP($B28,'4. CÀI ĐẶT'!$A$2:$H$32,6,FALSE))) | J28: =IF($A28="","",EOMONTH($A28,0)) | K28: =IF($B28="",0,IF(LEFT($B28,1)="━",0,$C28*VLOOKUP($B28,'4. CÀI ĐẶT'!$A$2:$H$32,7,FALSE)))
E29: =IF($B29="","",IF(LEFT($B29,1)="━","⚠️ Chọn hạng mục cụ thể",$C29*VLOOKUP($B29,'4. CÀI ĐẶT'!$A$2:$H$32,2,FALSE))) | F29: =IF($B29="",0,IF(LEFT($B29,1)="━",0,$C29*VLOOKUP($B29,'4. CÀI ĐẶT'!$A$2:$H$32,3,FALSE))) | G29: =IF($B29="",0,IF(LEFT($B29,1)="━",0,$C29*VLOOKUP($B29,'4. CÀI ĐẶT'!$A$2:$H$32,4,FALSE))) | H29: =IF($B29="",0,IF(LEFT($B29,1)="━",0,$C29*VLOOKUP($B29,'4. CÀI ĐẶT'!$A$2:$H$32,5,FALSE))) | I29: =IF($B29="","",IF(LEFT($B29,1)="━","",VLOOKUP($B29,'4. CÀI ĐẶT'!$A$2:$H$32,6,FALSE))) | J29: =IF($A29="","",EOMONTH($A29,0)) | K29: =IF($B29="",0,IF(LEFT($B29,1)="━",0,$C29*VLOOKUP($B29,'4. CÀI ĐẶT'!$A$2:$H$32,7,FALSE)))
E30: =IF($B30="","",IF(LEFT($B30,1)="━","⚠️ Chọn hạng mục cụ thể",$C30*VLOOKUP($B30,'4. CÀI ĐẶT'!$A$2:$H$32,2,FALSE))) | F30: =IF($B30="",0,IF(LEFT($B30,1)="━",0,$C30*VLOOKUP($B30,'4. CÀI ĐẶT'!$A$2:$H$32,3,FALSE))) | G30: =IF($B30="",0,IF(LEFT($B30,1)="━",0,$C30*VLOOKUP($B30,'4. CÀI ĐẶT'!$A$2:$H$32,4,FALSE))) | H30: =IF($B30="",0,IF(LEFT($B30,1)="━",0,$C30*VLOOKUP($B30,'4. CÀI ĐẶT'!$A$2:$H$32,5,FALSE))) | I30: =IF($B30="","",IF(LEFT($B30,1)="━","",VLOOKUP($B30,'4. CÀI ĐẶT'!$A$2:$H$32,6,FALSE))) | J30: =IF($A30="","",EOMONTH($A30,0)) | K30: =IF($B30="",0,IF(LEFT($B30,1)="━",0,$C30*VLOOKUP($B30,'4. CÀI ĐẶT'!$A$2:$H$32,7,FALSE)))
E31: =IF($B31="","",IF(LEFT($B31,1)="━","⚠️ Chọn hạng mục cụ thể",$C31*VLOOKUP($B31,'4. CÀI ĐẶT'!$A$2:$H$32,2,FALSE))) | F31: =IF($B31="",0,IF(LEFT($B31,1)="━",0,$C31*VLOOKUP($B31,'4. CÀI ĐẶT'!$A$2:$H$32,3,FALSE))) | G31: =IF($B31="",0,IF(LEFT($B31,1)="━",0,$C31*VLOOKUP($B31,'4. CÀI ĐẶT'!$A$2:$H$32,4,FALSE))) | H31: =IF($B31="",0,IF(LEFT($B31,1)="━",0,$C31*VLOOKUP($B31,'4. CÀI ĐẶT'!$A$2:$H$32,5,FALSE))) | I31: =IF($B31="","",IF(LEFT($B31,1)="━","",VLOOKUP($B31,'4. CÀI ĐẶT'!$A$2:$H$32,6,FALSE))) | J31: =IF($A31="","",EOMONTH($A31,0)) | K31: =IF($B31="",0,IF(LEFT($B31,1)="━",0,$C31*VLOOKUP($B31,'4. CÀI ĐẶT'!$A$2:$H$32,7,FALSE)))
... E2004: =IF($B2004="","",IF(LEFT($B2004,1)="━","⚠️ Chọn hạng mục cụ thể",$C2004*VLOOKUP($B2004,'4. CÀI ĐẶT'!$A$2:$H$32,2,FALSE))) | F2004: =IF($B2004="",0,IF(LEFT($B2004,1)="━",0,$C2004*VLOOKUP($B2004,'4. CÀI ĐẶT'!$A$2:$H$32,3,FALSE))) | G2004: =IF($B2004="",0,IF(LEFT($B2004,1)="━",0,$C2004*VLOOKUP($B2004,'4. CÀI ĐẶT'!$A$2:$H$32,4,FALSE))) | H2004: =IF($B2004="",0,IF(LEFT($B2004,1)="━",0,$C2004*VLOOKUP($B2004,'4. CÀI ĐẶT'!$A$2:$H$32,5,FALSE))) | I2004: =IF($B2004="","",IF(LEFT($B2004,1)="━","",VLOOKUP($B2004,'4. CÀI ĐẶT'!$A$2:$H$32,6,FALSE))) | J2004: =IF($A2004="","",EOMONTH($A2004,0)) | K2004: =IF($B2004="",0,IF(LEFT($B2004,1)="━",0,$C2004*VLOOKUP($B2004,'4. CÀI ĐẶT'!$A$2:$H$32,7,FALSE)))

Sheet 2. DASHBOARD
B1: =" 🩺 Kiểm Tra Nhanh Sức Khỏe Dòng Tiền Spa · Tháng "&TEXT(TODAY(),"mm/yyyy") | H1: ='4. CÀI ĐẶT'!$B$52
B2: Chị đã nhập tương đối đầy đủ thu – chi tháng này chưa? → | D2: Tương đối đầy đủ
B4: ='4. CÀI ĐẶT'!$C$52&" TÌNH TRẠNG CHUNG"
B5: ='4. CÀI ĐẶT'!$B$53
B7: BỐN ĐIỀU CẦN BIẾT VỀ THÁNG NÀY
B8: ① Tiền đã THU về | C8: ='4. CÀI ĐẶT'!$B$42
B9: ② Tiền đã CHI ra | C9: ='4. CÀI ĐẶT'!$B$43
B10: ③ Tháng này đang DƯ hay HỤT | C10: =IF('4. CÀI ĐẶT'!$B$39=0,"—",IF('4. CÀI ĐẶT'!$B$44>0,"Dư "&TEXT('4. CÀI ĐẶT'!$B$44,"#,##0")&" đ",IF('4. CÀI ĐẶT'!$B$44<0,"Hụt "&TEXT(-'4. CÀI ĐẶT'!$B$44,"#,##0")&" đ","Hòa")))
B11: ④ Nguy cơ từ tiền gói của khách | C11: ='4. CÀI ĐẶT'!$B$50
B12: ='4. CÀI ĐẶT'!$B$57
B14: ='4. CÀI ĐẶT'!$B$55
B15: 👉 VIỆC NÊN LÀM
B16: ='4. CÀI ĐẶT'!$B$54
B18: 🌿 Chị đã THẤY dấu hiệu. Muốn biết VÌ SAO & sửa từ đâu?
B19: Đăng ký Chẩn Đoán Sức Khỏe Spa cùng Đàm Thanh Hoa:
B20: 🔗 Link đăng ký: | C20: (điền vào đây)
B21: 📱 Mã QR: | C21: (điền vào đây)
B22: 🌐 Website / Zalo: | C22: (điền vào đây)
B24: Giải Pháp Đàm Hoa · Đàm Thị Thanh Hoa — 15 năm nghề spa, 6 chi nhánh.

Sheet 3. HƯỚNG DẪN
B1: 3️⃣ HƯỚNG DẪN — đọc 1 phút là dùng được
C3: DÙNG 5 BƯỚC
B4: 1 | C4: Bấm File → Tạo bản sao (bản của riêng chị).
B5: 2 | C5: Trả lời 1 câu ở đầu tab Nhập: spa có bán gói/liệu trình trả trước không (Có/Không).
B6: 3 | C6: Nhập thu – chi: trong ngày hoặc 2–3 lần mỗi tuần. Bỏ một ngày cũng không sao, cứ nhập bù.
B7: 4 | C7: Nếu có bán gói: mỗi tuần thêm 1 dòng “Giá trị dịch vụ gói đã làm trong tuần” (xem ví dụ dưới).
B8: 5 | C8: Mở Dashboard: gạt “đã nhập tương đối đầy đủ chưa?” rồi đọc 4 số + đèn + việc nên làm.
C10: NHẬP THẾ NÀO
B11: • | C11: Mỗi việc thu/ra = 1 dòng: NGÀY · HẠNG MỤC (bấm ▼) · SỐ TIỀN (luôn số dương). Ghi chú tuỳ ý.
B12: • | C12: Danh sách chia sẵn 6 nhóm. Dòng có gạch ━━ chỉ là TÊN NHÓM — chọn hạng mục bên dưới, đừng chọn dòng gạch (chọn nhầm bảng sẽ báo đỏ).
C14: VÍ DỤ NHẬP GÓI ĐÃ LÀM (mỗi tuần 1 dòng)
B15: • | C15: Khách mua gói 10 buổi giá 10 triệu → mỗi buổi 1 triệu. Tuần này chị làm 3 buổi → nhập 3 triệu.
B16: • | C16: Nhiều khách thì cộng tổng giá trị các buổi đã làm trong tuần, nhập 1 dòng. Không cần nhập từng khách, từng buổi.
C18: BỐN Ô TRÊN DASHBOARD
C19: ① Tiền đã thu về — tiền thật đã vào két tháng này. ② Tiền đã chi ra — tiền thật đã ra.
C20: ③ Dư hay hụt = thu − chi. Đây là câu hỏi về TIỀN MẶT trong tháng.
C21: ④ Nguy cơ tiền gói — spa có đang tiêu vào tiền khách trả trước cho dịch vụ chưa làm không.
C22: Lưu ý: “còn tiền trong két” và “dịch vụ có lãi” là hai việc khác nhau. Muốn biết spa có thật sự lãi không, đó là phần của bản Chẩn Đoán Sức Khỏe Spa.
C24: ĐÈN & KẾT LUẬN
B25: • | C25: 🟢 Ổn · 🟡 Cần chú ý · 🔴 Nguy hiểm · ⏳ Tạm tính (chưa xác nhận đủ) · ⚪ Chưa đủ dữ liệu.
B26: • | C26: Bảng chỉ bật đèn xanh/vàng/đỏ khi chị đã bấm “Tương đối đầy đủ”. Nhập thử vài dòng thì chỉ là “tạm tính”.
B27: • | C27: “Chưa đủ dữ liệu” KHÁC với “an toàn”. Thiếu dữ liệu thì bảng không kết luận spa khỏe.
C29: GẮN CHẨN ĐOÁN + GIỚI HẠN
C30: Cuối Dashboard có 3 ô vàng: dán Link đăng ký, Mã QR, Website/Zalo trước khi gửi khách. Bảng có sẵn 2000 dòng; gần đầy sẽ được nhắc tạo bản sao mới.
C32: Giải Pháp Đàm Hoa · Đàm Thị Thanh Hoa — 15 năm nghề spa, 6 chi nhánh. Đây là bản mình đang dùng thật.

Sheet 4. CÀI ĐẶT
A1: Hạng mục | B1: Hệ số TIỀN | C1: Hệ số DT | D1: Hệ số CP | E1: Hệ số QUỸ | F1: Nhóm CP | G1: Thu/Chi tháng | H1: Giải thích
A2: ━━━━━ 💰 TIỀN THU ━━━━━ | B2: 0 | C2: 0 | D2: 0 | E2: 0 | F2: — | G2: 0
A3: 💰 Khách lẻ trả tiền ngay | B3: 1 | C3: 1 | D3: 0 | E3: 0 | F3: — | G3: 1 | H3: Vừa vào két, vừa là doanh thu thật.
A4: 💰 Bán sản phẩm / mỹ phẩm | B4: 1 | C4: 1 | D4: 0 | E4: 0 | F4: — | G4: 1 | H4: Bán lẻ, giao hàng luôn.
A5: 💰 Khách trả nợ cũ | B5: 1 | C5: 0 | D5: 0 | E5: 0 | F5: — | G5: 1 | H5: Tiền vào két; doanh thu đã ghi từ lúc làm dịch vụ.
A6: ━━━━━ 🏠 TIỀN CHI CỐ ĐỊNH ━━━━━ | B6: 0 | C6: 0 | D6: 0 | E6: 0 | F6: — | G6: 0
A7: 🏠 Thuê mặt bằng | B7: -1 | C7: 0 | D7: 1 | E7: 0 | F7: Cố định | G7: -1 | H7: Vắng khách vẫn phải trả.
A8: 👩 Lương cứng nhân viên | B8: -1 | C8: 0 | D8: 1 | E8: 0 | F8: Cố định | G8: -1 | H8: Lương cố định.
A9: 💡 Điện · nước · internet | B9: -1 | C9: 0 | D9: 1 | E9: 0 | F9: Cố định | G9: -1
A10: 📣 Quảng cáo · marketing | B10: -1 | C10: 0 | D10: 1 | E10: 0 | F10: Cố định | G10: -1
A11: 📱 Phần mềm · điện thoại · phí khác | B11: -1 | C11: 0 | D11: 1 | E11: 0 | F11: Cố định | G11: -1
A12: 🔧 Sửa chữa · bảo trì nhỏ | B12: -1 | C12: 0 | D12: 1 | E12: 0 | F12: Cố định | G12: -1
A13: 📋 Thuế · phí · bảo hiểm | B13: -1 | C13: 0 | D13: 1 | E13: 0 | F13: Cố định | G13: -1
A14: 🏦 Lãi vay phải trả | B14: -1 | C14: 0 | D14: 1 | E14: 0 | F14: Cố định | G14: -1 | H14: Chỉ phần lãi. Gốc chọn 'Trả nợ gốc'.
A15: ━━━━━ 🧴 TIỀN CHI THEO KHÁCH ━━━━━ | B15: 0 | C15: 0 | D15: 0 | E15: 0 | F15: — | G15: 0
A16: 🧴 Mỹ phẩm · vật tư cho khách | B16: -1 | C16: 0 | D16: 1 | E16: 0 | F16: Biến đổi | G16: -1 | H16: Càng đông khách càng tốn.
A17: 💵 Hoa hồng · thưởng theo doanh số | B17: -1 | C17: 0 | D17: 1 | E17: 0 | F17: Biến đổi | G17: -1
A18: 📦 Nhập hàng về bán lại | B18: -1 | C18: 0 | D18: 1 | E18: 0 | F18: Biến đổi | G18: -1 | H18: Giá vốn hàng bán.
A19: 🚕 Chi phí khác theo khách | B19: -1 | C19: 0 | D19: 1 | E19: 0 | F19: Biến đổi | G19: -1
A20: ━━━━━ 🎟️ GÓI TRẢ TRƯỚC ━━━━━ | B20: 0 | C20: 0 | D20: 0 | E20: 0 | F20: — | G20: 0
A21: 🎟️ Bán gói trả trước | B21: 1 | C21: 0 | D21: 0 | E21: 1 | F21: — | G21: 1 | H21: ⚠️ Tiền vào nhưng chưa phải của chị — đang nợ khách số buổi.
A22: ✅ Giá trị dịch vụ gói đã làm trong tuần | B22: 0 | C22: 1 | D22: 0 | E22: -1 | F22: — | G22: 0 | H22: Mỗi tuần 1 dòng: tổng giá trị buổi gói đã làm trong tuần.
A23: ↩️ Hoàn tiền gói cho khách | B23: -1 | C23: 0 | D23: 0 | E23: -1 | F23: — | G23: -1 | H23: Trả lại tiền VÀ xoá phần buổi còn nợ.
A24: ━━━━━ 🏦 VỐN · VAY · ĐẦU TƯ ━━━━━ | B24: 0 | C24: 0 | D24: 0 | E24: 0 | F24: — | G24: 0
A25: 🏦 Vay tiền / mượn tiền | B25: 1 | C25: 0 | D25: 0 | E25: 0 | F25: — | G25: 1 | H25: Vào két nhưng không phải doanh thu.
A26: 👑 Chủ bỏ thêm vốn vào | B26: 1 | C26: 0 | D26: 0 | E26: 0 | F26: — | G26: 1 | H26: Tiền chủ bơm vào.
A27: 🏦 Trả nợ gốc | B27: -1 | C27: 0 | D27: 0 | E27: 0 | F27: — | G27: -1 | H27: Ra khỏi két nhưng không phải chi phí.
A28: 👑 Chủ rút tiền tiêu riêng | B28: -1 | C28: 0 | D28: 0 | E28: 0 | F28: — | G28: -1 | H28: Tiền chị lấy về, không phải chi phí spa.
A29: 🪑 Mua máy móc · đầu tư lớn | B29: -1 | C29: 0 | D29: 0 | E29: 0 | F29: — | G29: -1 | H29: Máy dùng nhiều năm, không tính hết vào 1 tháng.
A30: ━━━━━ 📝 GIAO DỊCH KHÁC ━━━━━ | B30: 0 | C30: 0 | D30: 0 | E30: 0 | F30: — | G30: 0
A31: ⚙️ Số dư đầu kỳ (tiền đang có sẵn) | B31: 1 | C31: 0 | D31: 0 | E31: 0 | F31: — | G31: 0 | H31: Nhập 1 lần lúc bắt đầu. Không phải doanh thu, không tính thu tháng.
A32: ✅ Đã làm dịch vụ — khách còn nợ tiền | B32: 0 | C32: 1 | D32: 0 | E32: 0 | F32: — | G32: 0 | H32: Có doanh thu mà chưa có tiền. Khách trả thì chọn 'Khách trả nợ cũ'.
A34: ▼ KHỐI TÍNH TOÁN — tự động
A35: Tháng này | B35: =EOMONTH(TODAY(),0)
A36: Tiền trong két (lũy kế) | B36: =SUM('1. NHẬP DỮ LIỆU'!$E$5:$E$2004)
A37: Quỹ gói còn nợ (lũy kế) | B37: =SUM('1. NHẬP DỮ LIỆU'!$H$5:$H$2004)
A38: Tiền thật sự (ngầm) | B38: =B36-B37
A39: Có giao dịch nào chưa (1/0) | B39: =IF(COUNT('1. NHẬP DỮ LIỆU'!$C$5:$C$2004)=0,0,1)
A40: Số dòng chọn nhầm tiêu đề | B40: =SUMPRODUCT(--(LEFT('1. NHẬP DỮ LIỆU'!$B$5:$B$2004,1)="━"),--('1. NHẬP DỮ LIỆU'!$C$5:$C$2004<>""))
A41: Số dòng đã dùng | B41: =COUNTA('1. NHẬP DỮ LIỆU'!$B$5:$B$2004)
...
